Workbook

Sheet Overview
A1: CST SILVER JUBILEE DEPARTMENTAL FOOTBALL TOURNAMENT
A2: League-cum-Knockout Format | 33 Teams | 8 Groups (A-H) | All matches at CST Artificial Turf
A4: TOURNAMENT SUMMARY
A5: Total Registered Teams | B5: 33
A6: Total Groups | B6: 8 (Group A to Group H)
A7: Group Sizes | B7: Group A = 5 teams (A1-A5) | Groups B-H = 4 teams each
A8: Venue | B8: CST Artificial Turf (single venue - one match at a time, no home/away)
A9: Group Stage Format | B9: Single round-robin (league) within each group
A10: Total Group Stage Matches | B10: 52
A11: Qualification | B11: Top 2 teams from each group (Winner + Runner-up) advance
A12: Teams Advancing to Knockout | B12: 16
A13: Knockout Rounds | B13: Round of 16 -> Quarter-finals -> Semi-finals -> Final
A14: Total Knockout Matches | B14: 16
A16: GROUP COMPOSITION
A17: Group | B17: No. of Teams | C17: Team Codes (example) | D17: Venue | E17: Matches (round-robin) | F17: Match Days
A18: Group A | B18: 5 | C18: A1, A2, A3, A4, A5 | D18: CST Artificial Turf | E18: 10 | F18: 5
A19: Group B | B19: 4 | C19: B1, B2, B3, B4 | E19: 6 | F19: 3
A20: Group C | B20: 4 | C20: C1, C2, C3, C4 | E20: 6 | F20: 3
A21: Group D | B21: 4 | C21: D1, D2, D3, D4 | E21: 6 | F21: 3
A22: Group E | B22: 4 | C22: E1, E2, E3, E4 | E22: 6 | F22: 3
A23: Group F | B23: 4 | C23: F1, F2, F3, F4 | E23: 6 | F23: 3
A24: Group G | B24: 4 | C24: G1, G2, G3, G4 | E24: 6 | F24: 3
A25: Group H | B25: 4 | C25: H1, H2, H3, H4 | E25: 6 | F25: 3
A27: SCHEDULE SUMMARY
A28: Tournament Dates | B28: Sat 26 Sep 2026 (opening, 6:30-8:30 PM) to Fri 30 Oct 2026 (Final)
A29: Weekday Slots | B29: 6:00-8:00 PM and 8:00-10:00 PM (2 matches)
A30: Weekend Slots | B30: 4:00-6:00 PM, 6:00-8:00 PM and 8:00-10:00 PM (3 matches)
A31: Group Stage | B31: 26 Sep - 18 Oct 2026 (52 matches)
A32: Round of 16 | B32: 19 - 22 Oct 2026 (8 matches)
A33: Quarter-Finals | B33: 23, 25 Oct 2026 (4 matches) - no match 24 Oct (ground engaged for BUSF); rest day 26 Oct
A34: Semi-Finals | B34: SF1 Tue 27 Oct & SF2 Wed 28 Oct 2026, 6:00-8:00 PM (one match per day)
A35: Final | B35: 3rd Place Match: Thu 29 Oct 2026, 6:00-8:00 PM | Final: Fri 30 Oct 2026, 6:00-8:00 PM
A36: Full schedule | B36: See "Match Schedule" sheet (68 matches) and "Team Schedule" sheet

Sheet Match Schedule
A1: CST SILVER JUBILEE DEPARTMENTAL FOOTBALL TOURNAMENT - MATCH SCHEDULE
A2: 26 September - 30 October 2026 | CST Artificial Turf | Weekdays: 6-8 PM & 8-10 PM | Weekends: 4-6 PM, 6-8 PM & 8-10 PM | Opening match: Sat 26 Sep, 6:30-8:30 PM
A3: Legend: yellow rows = weekend | orange = opening match | green = knockout | grey = rest day. Team names fill in automatically (knockout names appear once results are entered).
A5: Match No. | B5: Date | C5: Day | D5: Time | E5: Stage | F5: Group | G5: Team 1 | H5: Team 2 | I5: Team 1 Name | J5: Team 2 Name | K5: Remarks
A6: GROUP STAGE (52 matches: 26 Sep - 18 Oct 2026)
A7: 1 | B7: 46291 | C7: =TEXT(B7,"dddd") -> Saturday | D7: 6:30 PM - 8:30 PM | E7: Group Stage | F7: A | G7: A3 | H7: A4 | I7: =IFERROR(INDEX('Groups A-H'!$C$5:$C$58,MATCH(G7,'Groups A-H'!$B$5:$B$58,0)),"") -> Thromde Sherig | J7: =IFERROR(INDEX('Groups A-H'!$C$5:$C$58,MATCH(H7,'Groups A-H'!$B$5:$B$58,0)),"") -> Immigration | K7: OPENING MATCH (Group A) - inaugural ceremony
A8: 2 | B8: 46292 | C8: =TEXT(B8,"dddd") -> Sunday | D8: 4:00 PM - 6:00 PM | F8: D | G8: D1 | H8: D4 | I8: =IFERROR(INDEX('Groups A-H'!$C$5:$C$58,MATCH(G8,'Groups A-H'!$B$5:$B$58,0)),"") -> FI FC | J8: =IFERROR(INDEX('Groups A-H'!$C$5:$C$58,MATCH(H8,'Groups A-H'!$B$5:$B$58,0)),"") -> Druk Larjung
A9: 3 | B9: 46292 | C9: =TEXT(B9,"dddd") -> Sunday | D9: 6:00 PM - 8:00 PM | F9: H | G9: H1 | H9: H4 | I9: =IFERROR(INDEX('Groups A-H'!$C$5:$C$58,MATCH(G9,'Groups A-H'!$B$5:$B$58,0)),"") -> Bhutan Board Product Limited (BBPL) | J9: =IFERROR(INDEX('Groups A-H'!$C$5:$C$58,MATCH(H9,'Groups A-H'!$B$5:$B$58,0)),"") -> PTDP
A10: 4 | B10: 46292 | C10: =TEXT(B10,"dddd") -> Sunday | D10: 8:00 PM - 10:00 PM | F10: B | G10: B2 | H10: B3 | I10: =IFERROR(INDEX('Groups A-H'!$C$5:$C$58,MATCH(G10,'Groups A-H'!$B$5:$B$58,0)),"") -> Zimdra FC | J10: =IFERROR(INDEX('Groups A-H'!$C$5:$C$58,MATCH(H10,'Groups A-H'!$B$5:$B$58,0)),"") -> ICP, Phuentsholing
A11: 5 | B11: 46293 | C11: =TEXT(B11,"dddd") -> Monday | D11: 6:00 PM - 8:00 PM | F11: F | G11: F1 | H11: F4 | I11: =IFERROR(INDEX('Groups A-H'!$C$5:$C$58,MATCH(G11,'Groups A-H'!$B$5:$B$58,0)),"") -> BSMPL | J11: =IFERROR(INDEX('Groups A-H'!$C$5:$C$58,MATCH(H11,'Groups A-H'!$B$5:$B$58,0)),"") -> DGPC United
A12: 6 | B12: 46293 | C12: =TEXT(B12,"dddd") -> Monday | D12: 8:00 PM - 10:00 PM | F12: D | G12: D2 | H12: D3 | I12: =IFERROR(INDEX('Groups A-H'!$C$5:$C$58,MATCH(G12,'Groups A-H'!$B$5:$B$58,0)),"") -> 570 MW | J12: =IFERROR(INDEX('Groups A-H'!$C$5:$C$58,MATCH(H12,'Groups A-H'!$B$5:$B$58,0)),"") -> TCC
A13: 7 | B13: 46294 | C13: =TEXT(B13,"dddd") -> Tuesday | D13: 6:00 PM - 8:00 PM | F13: B | G13: B1 | H13: B4 | I13: =IFERROR(INDEX('Groups A-H'!$C$5:$C$58,MATCH(G13,'Groups A-H'!$B$5:$B$58,0)),"") -> BPC | J13: =IFERROR(INDEX('Groups A-H'!$C$5:$C$58,MATCH(H13,'Groups A-H'!$B$5:$B$58,0)),"") -> CST Kangtsey
A14: 8 | B14: 46294 | C14: =TEXT(B14,"dddd") -> Tuesday | D14: 8:00 PM - 10:00 PM | F14: H | G14: H2 | H14: H3 | I14: =IFERROR(INDEX('Groups A-H'!$C$5:$C$58,MATCH(G14,'Groups A-H'!$B$5:$B$58,0)),"") -> Tashi Metals | J14: =IFERROR(INDEX('Groups A-H'!$C$5:$C$58,MATCH(H14,'Groups A-H'!$B$5:$B$58,0)),"") -> Bhutan Lottery
A15: 9 | B15: 46295 | C15: =TEXT(B15,"dddd") -> Wednesday | D15: 6:00 PM - 8:00 PM | F15: A | G15: A2 | H15: A5 | I15: =IFERROR(INDEX('Groups A-H'!$C$5:$C$58,MATCH(G15,'Groups A-H'!$B$5:$B$58,0)),"") -> Pling Taxi | J15: =IFERROR(INDEX('Groups A-H'!$C$5:$C$58,MATCH(H15,'Groups A-H'!$B$5:$B$58,0)),"") -> BFAL
A16: 10 | B16: 46295 | C16: =TEXT(B16,"dddd") -> Wednesday | D16: 8:00 PM - 10:00 PM | F16: F | G16: F2 | H16: F3 | I16: =IFERROR(INDEX('Groups A-H'!$C$5:$C$58,MATCH(G16,'Groups A-H'!$B$5:$B$58,0)),"") -> OG United | J16: =IFERROR(INDEX('Groups A-H'!$C$5:$C$58,MATCH(H16,'Groups A-H'!$B$5:$B$58,0)),"") -> DFAL
A17: 11 | B17: 46296 | C17: =TEXT(B17,"dddd") -> Thursday | D17: 6:00 PM - 8:00 PM | F17: C | G17: C1 | H17: C4 | I17: =IFERROR(INDEX('Groups A-H'!$C$5:$C$58,MATCH(G17,'Groups A-H'!$B$5:$B$58,0)),"") -> BCCL | J17: =IFERROR(INDEX('Groups A-H'!$C$5:$C$58,MATCH(H17,'Groups A-H'!$B$5:$B$58,0)),"") -> STCBL
A18: 12 | B18: 46296 | C18: =TEXT(B18,"dddd") -> Thursday | D18: 8:00 PM - 10:00 PM | F18: C | G18: C2 | H18: C3 | I18: =IFERROR(INDEX('Groups A-H'!$C$5:$C$58,MATCH(G18,'Groups A-H'!$B$5:$B$58,0)),"") -> GCBS | J18: =IFERROR(INDEX('Groups A-H'!$C$5:$C$58,MATCH(H18,'Groups A-H'!$B$5:$B$58,0)),"") -> Pling Hospital
A19: 13 | B19: 46297 | C19: =TEXT(B19,"dddd") -> Friday | D19: 6:00 PM - 8:00 PM | F19: A | G19: A1 | H19: A5 | I19: =IFERROR(INDEX('Groups A-H'!$C$5:$C$58,MATCH(G19,'Groups A-H'!$B$5:$B$58,0)),"") -> BBPL (Bhutan Brewary Private Limited) | J19: =IFERROR(INDEX('Groups A-H'!$C$5:$C$58,MATCH(H19,'Groups A-H'!$B$5:$B$58,0)),"") -> BFAL
... A34: 28 | B34: 46303 | C34: =TEXT(B34,"dddd") -> Thursday | D34: 8:00 PM - 10:00 PM | F34: H | G34: H4 | H34: H2 | I34: =IFERROR(INDEX('Groups A-H'!$C$5:$C$58,MATCH(G34,'Groups A-H'!$B$5:$B$58,0)),"") -> PTDP | J34: =IFERROR(INDEX('Groups A-H'!$C$5:$C$58,MATCH(H34,'Groups A-H'!$B$5:$B$58,0)),"") -> Tashi Metals
A35: 29 | B35: 46304 | C35: =TEXT(B35,"dddd") -> Friday | D35: 6:00 PM - 8:00 PM | F35: B | G35: B1 | H35: B2 | I35: =IFERROR(INDEX('Groups A-H'!$C$5:$C$58,MATCH(G35,'Groups A-H'!$B$5:$B$58,0)),"") -> BPC | J35: =IFERROR(INDEX('Groups A-H'!$C$5:$C$58,MATCH(H35,'Groups A-H'!$B$5:$B$58,0)),"") -> Zimdra FC | K35: Group B final matchday
A36: 30 | B36: 46304 | C36: =TEXT(B36,"dddd") -> Friday | D36: 8:00 PM - 10:00 PM | F36: B | G36: B3 | H36: B4 | I36: =IFERROR(INDEX('Groups A-H'!$C$5:$C$58,MATCH(G36,'Groups A-H'!$B$5:$B$58,0)),"") -> ICP, Phuentsholing | J36: =IFERROR(INDEX('Groups A-H'!$C$5:$C$58,MATCH(H36,'Groups A-H'!$B$5:$B$58,0)),"") -> CST Kangtsey | K36: Group B final matchday
A37: 31 | B37: 46305 | C37: =TEXT(B37,"dddd") -> Saturday | D37: 4:00 PM - 6:00 PM | F37: C | G37: C1 | H37: C3 | I37: =IFERROR(INDEX('Groups A-H'!$C$5:$C$58,MATCH(G37,'Groups A-H'!$B$5:$B$58,0)),"") -> BCCL | J37: =IFERROR(INDEX('Groups A-H'!$C$5:$C$58,MATCH(H37,'Groups A-H'!$B$5:$B$58,0)),"") -> Pling Hospital
A38: 32 | B38: 46305 | C38: =TEXT(B38,"dddd") -> Saturday | D38: 6:00 PM - 8:00 PM | F38: C | G38: C4 | H38: C2 | I38: =IFERROR(INDEX('Groups A-H'!$C$5:$C$58,MATCH(G38,'Groups A-H'!$B$5:$B$58,0)),"") -> STCBL | J38: =IFERROR(INDEX('Groups A-H'!$C$5:$C$58,MATCH(H38,'Groups A-H'!$B$5:$B$58,0)),"") -> GCBS
A39: 33 | B39: 46305 | C39: =TEXT(B39,"dddd") -> Saturday | D39: 8:00 PM - 10:00 PM | F39: A | G39: A2 | H39: A3 | I39: =IFERROR(INDEX('Groups A-H'!$C$5:$C$58,MATCH(G39,'Groups A-H'!$B$5:$B$58,0)),"") -> Pling Taxi | J39: =IFERROR(INDEX('Groups A-H'!$C$5:$C$58,MATCH(H39,'Groups A-H'!$B$5:$B$58,0)),"") -> Thromde Sherig
A40: 34 | B40: 46306 | C40: =TEXT(B40,"dddd") -> Sunday | D40: 4:00 PM - 6:00 PM | F40: E | G40: E1 | H40: E3 | I40: =IFERROR(INDEX('Groups A-H'!$C$5:$C$58,MATCH(G40,'Groups A-H'!$B$5:$B$58,0)),"") -> MDP FC | J40: =IFERROR(INDEX('Groups A-H'!$C$5:$C$58,MATCH(H40,'Groups A-H'!$B$5:$B$58,0)),"") -> Pelden Warriors
A41: 35 | B41: 46306 | C41: =TEXT(B41,"dddd") -> Sunday | D41: 6:00 PM - 8:00 PM | F41: G | G41: G1 | H41: G3 | I41: =IFERROR(INDEX('Groups A-H'!$C$5:$C$58,MATCH(G41,'Groups A-H'!$B$5:$B$58,0)),"") -> RICBL | J41: =IFERROR(INDEX('Groups A-H'!$C$5:$C$58,MATCH(H41,'Groups A-H'!$B$5:$B$58,0)),"") -> Coca Cola
A42: 36 | B42: 46306 | C42: =TEXT(B42,"dddd") -> Sunday | D42: 8:00 PM - 10:00 PM | F42: G | G42: G4 | H42: G2 | I42: =IFERROR(INDEX('Groups A-H'!$C$5:$C$58,MATCH(G42,'Groups A-H'!$B$5:$B$58,0)),"") -> BEA | J42: =IFERROR(INDEX('Groups A-H'!$C$5:$C$58,MATCH(H42,'Groups A-H'!$B$5:$B$58,0)),"") -> BOBL
A43: 37 | B43: 46307 | C43: =TEXT(B43,"dddd") -> Monday | D43: 6:00 PM - 8:00 PM | F43: A | G43: A1 | H43: A3 | I43: =IFERROR(INDEX('Groups A-H'!$C$5:$C$58,MATCH(G43,'Groups A-H'!$B$5:$B$58,0)),"") -> BBPL (Bhutan Brewary Private Limited) | J43: =IFERROR(INDEX('Groups A-H'!$C$5:$C$58,MATCH(H43,'Groups A-H'!$B$5:$B$58,0)),"") -> Thromde Sherig
A44: 38 | B44: 46307 | C44: =TEXT(B44,"dddd") -> Monday | D44: 8:00 PM - 10:00 PM | F44: A | G44: A4 | H44: A2 | I44: =IFERROR(INDEX('Groups A-H'!$C$5:$C$58,MATCH(G44,'Groups A-H'!$B$5:$B$58,0)),"") -> Immigration | J44: =IFERROR(INDEX('Groups A-H'!$C$5:$C$58,MATCH(H44,'Groups A-H'!$B$5:$B$58,0)),"") -> Pling Taxi
A45: 39 | B45: 46308 | C45: =TEXT(B45,"dddd") -> Tuesday | D45: 6:00 PM - 8:00 PM | F45: E | G45: E1 | H45: E2 | I45: =IFERROR(INDEX('Groups A-H'!$C$5:$C$58,MATCH(G45,'Groups A-H'!$B$5:$B$58,0)),"") -> MDP FC | J45: =IFERROR(INDEX('Groups A-H'!$C$5:$C$58,MATCH(H45,'Groups A-H'!$B$5:$B$58,0)),"") -> CST United
A46: 40 | B46: 46308 | C46: =TEXT(B46,"dddd") -> Tuesday | D46: 8:00 PM - 10:00 PM | F46: F | G46: F3 | H46: F4 | I46: =IFERROR(INDEX('Groups A-H'!$C$5:$C$58,MATCH(G46,'Groups A-H'!$B$5:$B$58,0)),"") -> DFAL | J46: =IFERROR(INDEX('Groups A-H'!$C$5:$C$58,MATCH(H46,'Groups A-H'!$B$5:$B$58,0)),"") -> DGPC United | K46: Group F final matchday
A47: 41 | B47: 46309 | C47: =TEXT(B47,"dddd") -> Wednesday | D47: 6:00 PM - 8:00 PM | F47: D | G47: D1 | H47: D2 | I47: =IFERROR(INDEX('Groups A-H'!$C$5:$C$58,MATCH(G47,'Groups A-H'!$B$5:$B$58,0)),"") -> FI FC | J47: =IFERROR(INDEX('Groups A-H'!$C$5:$C$58,MATCH(H47,'Groups A-H'!$B$5:$B$58,0)),"") -> 570 MW | K47: Group D final matchday
A48: 42 | B48: 46309 | C48: =TEXT(B48,"dddd") -> Wednesday | D48: 8:00 PM - 10:00 PM | F48: D | G48: D3 | H48: D4 | I48: =IFERROR(INDEX('Groups A-H'!$C$5:$C$58,MATCH(G48,'Groups A-H'!$B$5:$B$58,0)),"") -> TCC | J48: =IFERROR(INDEX('Groups A-H'!$C$5:$C$58,MATCH(H48,'Groups A-H'!$B$5:$B$58,0)),"") -> Druk Larjung | K48: Group D final matchday
A49: 43 | B49: 46310 | C49: =TEXT(B49,"dddd") -> Thursday | D49: 6:00 PM - 8:00 PM | F49: C | G49: C1 | H49: C2 | I49: =IFERROR(INDEX('Groups A-H'!$C$5:$C$58,MATCH(G49,'Groups A-H'!$B$5:$B$58,0)),"") -> BCCL | J49: =IFERROR(INDEX('Groups A-H'!$C$5:$C$58,MATCH(H49,'Groups A-H'!$B$5:$B$58,0)),"") -> GCBS | K49: Group C final matchday
A50: 44 | B50: 46310 | C50: =TEXT(B50,"dddd") -> Thursday | D50: 8:00 PM - 10:00 PM | F50: C | G50: C3 | H50: C4 | I50: =IFERROR(INDEX('Groups A-H'!$C$5:$C$58,MATCH(G50,'Groups A-H'!$B$5:$B$58,0)),"") -> Pling Hospital | J50: =IFERROR(INDEX('Groups A-H'!$C$5:$C$58,MATCH(H50,'Groups A-H'!$B$5:$B$58,0)),"") -> STCBL | K50: Group C final matchday
A51: 45 | B51: 46311 | C51: =TEXT(B51,"dddd") -> Friday | D51: 6:00 PM - 8:00 PM | F51: A | G51: A1 | H51: A2 | I51: =IFERROR(INDEX('Groups A-H'!$C$5:$C$58,MATCH(G51,'Groups A-H'!$B$5:$B$58,0)),"") -> BBPL (Bhutan Brewary Private Limited) | J51: =IFERROR(INDEX('Groups A-H'!$C$5:$C$58,MATCH(H51,'Groups A-H'!$B$5:$B$58,0)),"") -> Pling Taxi | K51: Group A final matchday
A52: 46 | B52: 46311 | C52: =TEXT(B52,"dddd") -> Friday | D52: 8:00 PM - 10:00 PM | F52: A | G52: A4 | H52: A5 | I52: =IFERROR(INDEX('Groups A-H'!$C$5:$C$58,MATCH(G52,'Groups A-H'!$B$5:$B$58,0)),"") -> Immigration | J52: =IFERROR(INDEX('Groups A-H'!$C$5:$C$58,MATCH(H52,'Groups A-H'!$B$5:$B$58,0)),"") -> BFAL | K52: Group A final matchday
A53: 47 | B53: 46312 | C53: =TEXT(B53,"dddd") -> Saturday | D53: 4:00 PM - 6:00 PM | F53: G | G53: G1 | H53: G2 | I53: =IFERROR(INDEX('Groups A-H'!$C$5:$C$58,MATCH(G53,'Groups A-H'!$B$5:$B$58,0)),"") -> RICBL | J53: =IFERROR(INDEX('Groups A-H'!$C$5:$C$58,MATCH(H53,'Groups A-H'!$B$5:$B$58,0)),"") -> BOBL | K53: Group G final matchday
A54: 48 | B54: 46312 | C54: =TEXT(B54,"dddd") -> Saturday | D54: 6:00 PM - 8:00 PM | F54: G | G54: G3 | H54: G4 | I54: =IFERROR(INDEX('Groups A-H'!$C$5:$C$58,MATCH(G54,'Groups A-H'!$B$5:$B$58,0)),"") -> Coca Cola | J54: =IFERROR(INDEX('Groups A-H'!$C$5:$C$58,MATCH(H54,'Groups A-H'!$B$5:$B$58,0)),"") -> BEA | K54: Group G final matchday
A55: 49 | B55: 46312 | C55: =TEXT(B55,"dddd") -> Saturday | D55: 8:00 PM - 10:00 PM | F55: H | G55: H3 | H55: H4 | I55: =IFERROR(INDEX('Groups A-H'!$C$5:$C$58,MATCH(G55,'Groups A-H'!$B$5:$B$58,0)),"") -> Bhutan Lottery | J55: =IFERROR(INDEX('Groups A-H'!$C$5:$C$58,MATCH(H55,'Groups A-H'!$B$5:$B$58,0)),"") -> PTDP | K55: Group H final matchday
...

Sheet Team Schedule
A1: GROUP-STAGE SCHEDULE BY TEAM (rest-day check)
A2: Match numbers refer to the "Match No." column on the Match Schedule sheet. Min. Rest Days = fewest clear days between two consecutive matches of the team.
A4: Team | B4: Team Name | C4: Group | D4: Match 1 | E4: Date | F4: Match 2 | G4: Date | H4: Match 3 | I4: Date | J4: Match 4 | K4: Date | L4: Min. Rest Days
A5: A1 | B5: =IFERROR(INDEX('Groups A-H'!$C$5:$C$58,MATCH(A5,'Groups A-H'!$B$5:$B$58,0)),"") -> BBPL (Bhutan Brewary Private Limited) | C5: A | D5: 13 | E5: =INDEX('Match Schedule'!$B$6:$B$79,MATCH(D5,'Match Schedule'!$A$6:$A$79,0)) -> 46297 | F5: 25 | G5: =INDEX('Match Schedule'!$B$6:$B$79,MATCH(F5,'Match Schedule'!$A$6:$A$79,0)) -> 46302 | H5: 37 | I5: =INDEX('Match Schedule'!$B$6:$B$79,MATCH(H5,'Match Schedule'!$A$6:$A$79,0)) -> 46307 | J5: 45 | K5: =INDEX('Match Schedule'!$B$6:$B$79,MATCH(J5,'Match Schedule'!$A$6:$A$79,0)) -> 46311 | L5: =MIN(G5-E5,I5-G5,K5-I5)-1 -> 3
A6: A2 | B6: =IFERROR(INDEX('Groups A-H'!$C$5:$C$58,MATCH(A6,'Groups A-H'!$B$5:$B$58,0)),"") -> Pling Taxi | C6: A | D6: 9 | E6: =INDEX('Match Schedule'!$B$6:$B$79,MATCH(D6,'Match Schedule'!$A$6:$A$79,0)) -> 46295 | F6: 33 | G6: =INDEX('Match Schedule'!$B$6:$B$79,MATCH(F6,'Match Schedule'!$A$6:$A$79,0)) -> 46305 | H6: 38 | I6: =INDEX('Match Schedule'!$B$6:$B$79,MATCH(H6,'Match Schedule'!$A$6:$A$79,0)) -> 46307 | J6: 45 | K6: =INDEX('Match Schedule'!$B$6:$B$79,MATCH(J6,'Match Schedule'!$A$6:$A$79,0)) -> 46311 | L6: =MIN(G6-E6,I6-G6,K6-I6)-1 -> 1
A7: A3 | B7: =IFERROR(INDEX('Groups A-H'!$C$5:$C$58,MATCH(A7,'Groups A-H'!$B$5:$B$58,0)),"") -> Thromde Sherig | C7: A | D7: 1 | E7: =INDEX('Match Schedule'!$B$6:$B$79,MATCH(D7,'Match Schedule'!$A$6:$A$79,0)) -> 46291 | F7: 26 | G7: =INDEX('Match Schedule'!$B$6:$B$79,MATCH(F7,'Match Schedule'!$A$6:$A$79,0)) -> 46302 | H7: 33 | I7: =INDEX('Match Schedule'!$B$6:$B$79,MATCH(H7,'Match Schedule'!$A$6:$A$79,0)) -> 46305 | J7: 37 | K7: =INDEX('Match Schedule'!$B$6:$B$79,MATCH(J7,'Match Schedule'!$A$6:$A$79,0)) -> 46307 | L7: =MIN(G7-E7,I7-G7,K7-I7)-1 -> 1
A8: A4 | B8: =IFERROR(INDEX('Groups A-H'!$C$5:$C$58,MATCH(A8,'Groups A-H'!$B$5:$B$58,0)),"") -> Immigration | C8: A | D8: 1 | E8: =INDEX('Match Schedule'!$B$6:$B$79,MATCH(D8,'Match Schedule'!$A$6:$A$79,0)) -> 46291 | F8: 25 | G8: =INDEX('Match Schedule'!$B$6:$B$79,MATCH(F8,'Match Schedule'!$A$6:$A$79,0)) -> 46302 | H8: 38 | I8: =INDEX('Match Schedule'!$B$6:$B$79,MATCH(H8,'Match Schedule'!$A$6:$A$79,0)) -> 46307 | J8: 46 | K8: =INDEX('Match Schedule'!$B$6:$B$79,MATCH(J8,'Match Schedule'!$A$6:$A$79,0)) -> 46311 | L8: =MIN(G8-E8,I8-G8,K8-I8)-1 -> 3
A9: A5 | B9: =IFERROR(INDEX('Groups A-H'!$C$5:$C$58,MATCH(A9,'Groups A-H'!$B$5:$B$58,0)),"") -> BFAL | C9: A | D9: 9 | E9: =INDEX('Match Schedule'!$B$6:$B$79,MATCH(D9,'Match Schedule'!$A$6:$A$79,0)) -> 46295 | F9: 13 | G9: =INDEX('Match Schedule'!$B$6:$B$79,MATCH(F9,'Match Schedule'!$A$6:$A$79,0)) -> 46297 | H9: 26 | I9: =INDEX('Match Schedule'!$B$6:$B$79,MATCH(H9,'Match Schedule'!$A$6:$A$79,0)) -> 46302 | J9: 46 | K9: =INDEX('Match Schedule'!$B$6:$B$79,MATCH(J9,'Match Schedule'!$A$6:$A$79,0)) -> 46311 | L9: =MIN(G9-E9,I9-G9,K9-I9)-1 -> 1
A10: B1 | B10: =IFERROR(INDEX('Groups A-H'!$C$5:$C$58,MATCH(A10,'Groups A-H'!$B$5:$B$58,0)),"") -> BPC | C10: B | D10: 7 | E10: =INDEX('Match Schedule'!$B$6:$B$79,MATCH(D10,'Match Schedule'!$A$6:$A$79,0)) -> 46294 | F10: 15 | G10: =INDEX('Match Schedule'!$B$6:$B$79,MATCH(F10,'Match Schedule'!$A$6:$A$79,0)) -> 46298 | H10: 29 | I10: =INDEX('Match Schedule'!$B$6:$B$79,MATCH(H10,'Match Schedule'!$A$6:$A$79,0)) -> 46304 | L10: =MIN(G10-E10,I10-G10)-1 -> 3
A11: B2 | B11: =IFERROR(INDEX('Groups A-H'!$C$5:$C$58,MATCH(A11,'Groups A-H'!$B$5:$B$58,0)),"") -> Zimdra FC | C11: B | D11: 4 | E11: =INDEX('Match Schedule'!$B$6:$B$79,MATCH(D11,'Match Schedule'!$A$6:$A$79,0)) -> 46292 | F11: 16 | G11: =INDEX('Match Schedule'!$B$6:$B$79,MATCH(F11,'Match Schedule'!$A$6:$A$79,0)) -> 46298 | H11: 29 | I11: =INDEX('Match Schedule'!$B$6:$B$79,MATCH(H11,'Match Schedule'!$A$6:$A$79,0)) -> 46304 | L11: =MIN(G11-E11,I11-G11)-1 -> 5
A12: B3 | B12: =IFERROR(INDEX('Groups A-H'!$C$5:$C$58,MATCH(A12,'Groups A-H'!$B$5:$B$58,0)),"") -> ICP, Phuentsholing | C12: B | D12: 4 | E12: =INDEX('Match Schedule'!$B$6:$B$79,MATCH(D12,'Match Schedule'!$A$6:$A$79,0)) -> 46292 | F12: 15 | G12: =INDEX('Match Schedule'!$B$6:$B$79,MATCH(F12,'Match Schedule'!$A$6:$A$79,0)) -> 46298 | H12: 30 | I12: =INDEX('Match Schedule'!$B$6:$B$79,MATCH(H12,'Match Schedule'!$A$6:$A$79,0)) -> 46304 | L12: =MIN(G12-E12,I12-G12)-1 -> 5
A13: B4 | B13: =IFERROR(INDEX('Groups A-H'!$C$5:$C$58,MATCH(A13,'Groups A-H'!$B$5:$B$58,0)),"") -> CST Kangtsey | C13: B | D13: 7 | E13: =INDEX('Match Schedule'!$B$6:$B$79,MATCH(D13,'Match Schedule'!$A$6:$A$79,0)) -> 46294 | F13: 16 | G13: =INDEX('Match Schedule'!$B$6:$B$79,MATCH(F13,'Match Schedule'!$A$6:$A$79,0)) -> 46298 | H13: 30 | I13: =INDEX('Match Schedule'!$B$6:$B$79,MATCH(H13,'Match Schedule'!$A$6:$A$79,0)) -> 46304 | L13: =MIN(G13-E13,I13-G13)-1 -> 3
A14: C1 | B14: =IFERROR(INDEX('Groups A-H'!$C$5:$C$58,MATCH(A14,'Groups A-H'!$B$5:$B$58,0)),"") -> BCCL | C14: C | D14: 11 | E14: =INDEX('Match Schedule'!$B$6:$B$79,MATCH(D14,'Match Schedule'!$A$6:$A$79,0)) -> 46296 | F14: 31 | G14: =INDEX('Match Schedule'!$B$6:$B$79,MATCH(F14,'Match Schedule'!$A$6:$A$79,0)) -> 46305 | H14: 43 | I14: =INDEX('Match Schedule'!$B$6:$B$79,MATCH(H14,'Match Schedule'!$A$6:$A$79,0)) -> 46310 | L14: =MIN(G14-E14,I14-G14)-1 -> 4
A15: C2 | B15: =IFERROR(INDEX('Groups A-H'!$C$5:$C$58,MATCH(A15,'Groups A-H'!$B$5:$B$58,0)),"") -> GCBS | C15: C | D15: 12 | E15: =INDEX('Match Schedule'!$B$6:$B$79,MATCH(D15,'Match Schedule'!$A$6:$A$79,0)) -> 46296 | F15: 32 | G15: =INDEX('Match Schedule'!$B$6:$B$79,MATCH(F15,'Match Schedule'!$A$6:$A$79,0)) -> 46305 | H15: 43 | I15: =INDEX('Match Schedule'!$B$6:$B$79,MATCH(H15,'Match Schedule'!$A$6:$A$79,0)) -> 46310 | L15: =MIN(G15-E15,I15-G15)-1 -> 4
A16: C3 | B16: =IFERROR(INDEX('Groups A-H'!$C$5:$C$58,MATCH(A16,'Groups A-H'!$B$5:$B$58,0)),"") -> Pling Hospital | C16: C | D16: 12 | E16: =INDEX('Match Schedule'!$B$6:$B$79,MATCH(D16,'Match Schedule'!$A$6:$A$79,0)) -> 46296 | F16: 31 | G16: =INDEX('Match Schedule'!$B$6:$B$79,MATCH(F16,'Match Schedule'!$A$6:$A$79,0)) -> 46305 | H16: 44 | I16: =INDEX('Match Schedule'!$B$6:$B$79,MATCH(H16,'Match Schedule'!$A$6:$A$79,0)) -> 46310 | L16: =MIN(G16-E16,I16-G16)-1 -> 4
A17: C4 | B17: =IFERROR(INDEX('Groups A-H'!$C$5:$C$58,MATCH(A17,'Groups A-H'!$B$5:$B$58,0)),"") -> STCBL | C17: C | D17: 11 | E17: =INDEX('Match Schedule'!$B$6:$B$79,MATCH(D17,'Match Schedule'!$A$6:$A$79,0)) -> 46296 | F17: 32 | G17: =INDEX('Match Schedule'!$B$6:$B$79,MATCH(F17,'Match Schedule'!$A$6:$A$79,0)) -> 46305 | H17: 44 | I17: =INDEX('Match Schedule'!$B$6:$B$79,MATCH(H17,'Match Schedule'!$A$6:$A$79,0)) -> 46310 | L17: =MIN(G17-E17,I17-G17)-1 -> 4
A18: D1 | B18: =IFERROR(INDEX('Groups A-H'!$C$5:$C$58,MATCH(A18,'Groups A-H'!$B$5:$B$58,0)),"") -> FI FC | C18: D | D18: 2 | E18: =INDEX('Match Schedule'!$B$6:$B$79,MATCH(D18,'Match Schedule'!$A$6:$A$79,0)) -> 46292 | F18: 18 | G18: =INDEX('Match Schedule'!$B$6:$B$79,MATCH(F18,'Match Schedule'!$A$6:$A$79,0)) -> 46299 | H18: 41 | I18: =INDEX('Match Schedule'!$B$6:$B$79,MATCH(H18,'Match Schedule'!$A$6:$A$79,0)) -> 46309 | L18: =MIN(G18-E18,I18-G18)-1 -> 6
A19: D2 | B19: =IFERROR(INDEX('Groups A-H'!$C$5:$C$58,MATCH(A19,'Groups A-H'!$B$5:$B$58,0)),"") -> 570 MW | C19: D | D19: 6 | E19: =INDEX('Match Schedule'!$B$6:$B$79,MATCH(D19,'Match Schedule'!$A$6:$A$79,0)) -> 46293 | F19: 19 | G19: =INDEX('Match Schedule'!$B$6:$B$79,MATCH(F19,'Match Schedule'!$A$6:$A$79,0)) -> 46299 | H19: 41 | I19: =INDEX('Match Schedule'!$B$6:$B$79,MATCH(H19,'Match Schedule'!$A$6:$A$79,0)) -> 46309 | L19: =MIN(G19-E19,I19-G19)-1 -> 5
A20: D3 | B20: =IFERROR(INDEX('Groups A-H'!$C$5:$C$58,MATCH(A20,'Groups A-H'!$B$5:$B$58,0)),"") -> TCC | C20: D | D20: 6 | E20: =INDEX('Match Schedule'!$B$6:$B$79,MATCH(D20,'Match Schedule'!$A$6:$A$79,0)) -> 46293 | F20: 18 | G20: =INDEX('Match Schedule'!$B$6:$B$79,MATCH(F20,'Match Schedule'!$A$6:$A$79,0)) -> 46299 | H20: 42 | I20: =INDEX('Match Schedule'!$B$6:$B$79,MATCH(H20,'Match Schedule'!$A$6:$A$79,0)) -> 46309 | L20: =MIN(G20-E20,I20-G20)-1 -> 5
A21: D4 | B21: =IFERROR(INDEX('Groups A-H'!$C$5:$C$58,MATCH(A21,'Groups A-H'!$B$5:$B$58,0)),"") -> Druk Larjung | C21: D | D21: 2 | E21: =INDEX('Match Schedule'!$B$6:$B$79,MATCH(D21,'Match Schedule'!$A$6:$A$79,0)) -> 46292 | F21: 19 | G21: =INDEX('Match Schedule'!$B$6:$B$79,MATCH(F21,'Match Schedule'!$A$6:$A$79,0)) -> 46299 | H21: 42 | I21: =INDEX('Match Schedule'!$B$6:$B$79,MATCH(H21,'Match Schedule'!$A$6:$A$79,0)) -> 46309 | L21: =MIN(G21-E21,I21-G21)-1 -> 6
... A37: H4 | B37: =IFERROR(INDEX('Groups A-H'!$C$5:$C$58,MATCH(A37,'Groups A-H'!$B$5:$B$58,0)),"") -> PTDP | C37: H | D37: 3 | E37: =INDEX('Match Schedule'!$B$6:$B$79,MATCH(D37,'Match Schedule'!$A$6:$A$79,0)) -> 46292 | F37: 28 | G37: =INDEX('Match Schedule'!$B$6:$B$79,MATCH(F37,'Match Schedule'!$A$6:$A$79,0)) -> 46303 | H37: 49 | I37: =INDEX('Match Schedule'!$B$6:$B$79,MATCH(H37,'Match Schedule'!$A$6:$A$79,0)) -> 46312 | L37: =MIN(G37-E37,I37-G37)-1 -> 8

Sheet Groups A-H
A1: GROUP DRAW - GROUP A TO GROUP H
A3: GROUP A
A4: Slot | B4: Team Code | C4: Team Name | D4: Status
A5: 1 | B5: A1 | C5: BBPL (Bhutan Brewary Private Limited) | D5: Registered
A6: 2 | B6: A2 | C6: Pling Taxi | D6: Registered
A7: 3 | B7: A3 | C7: Thromde Sherig | D7: Registered
A8: 4 | B8: A4 | C8: Immigration | D8: Registered
A9: 5 | B9: A5 | C9: BFAL | D9: Registered
A11: GROUP B
A12: Slot | B12: Team Code | C12: Team Name | D12: Status
A13: 1 | B13: B1 | C13: BPC | D13: Registered
A14: 2 | B14: B2 | C14: Zimdra FC | D14: Registered
A15: 3 | B15: B3 | C15: ICP, Phuentsholing | D15: Registered
A16: 4 | B16: B4 | C16: CST Kangtsey | D16: Registered
A18: GROUP C
A19: Slot | B19: Team Code | C19: Team Name | D19: Status
A20: 1 | B20: C1 | C20: BCCL | D20: Registered
A21: 2 | B21: C2 | C21: GCBS | D21: Registered
A22: 3 | B22: C3 | C22: Pling Hospital | D22: Registered
A23: 4 | B23: C4 | C23: STCBL | D23: Registered
A25: GROUP D
A26: Slot | B26: Team Code | C26: Team Name | D26: Status
A27: 1 | B27: D1 | C27: FI FC | D27: Registered
A28: 2 | B28: D2 | C28: 570 MW | D28: Registered
A29: 3 | B29: D3 | C29: TCC | D29: Registered
A30: 4 | B30: D4 | C30: Druk Larjung | D30: Registered
A32: GROUP E
A33: Slot | B33: Team Code | C33: Team Name | D33: Status
A34: 1 | B34: E1 | C34: MDP FC | D34: Registered
A35: 2 | B35: E2 | C35: CST United | D35: Registered
A36: 3 | B36: E3 | C36: Pelden Warriors | D36: Registered
A37: 4 | B37: E4 | C37: FCB | D37: Registered
A39: GROUP F
A40: Slot | B40: Team Code | C40: Team Name | D40: Status
A41: 1 | B41: F1 | C41: BSMPL | D41: Registered
A42: 2 | B42: F2 | C42: OG United | D42: Registered
A43: 3 | B43: F3 | C43: DFAL | D43: Registered
A44: 4 | B44: F4 | C44: DGPC United | D44: Registered
A46: GROUP G
A47: Slot | B47: Team Code | C47: Team Name | D47: Status
...

Sheet Group Fixtures
A1: GROUP STAGE FIXTURES (ROUND-ROBIN, LEAGUE FORMAT)
A2: Enter final scores in the "Score 1" / "Score 2" columns (yellow) once played. Single venue - matches are played one at a time in Match Day / Match No. order, no home or away side.
A4: GROUP A
A5: Match No. | B5: Match Day | C5: Team 1 | D5: Team 2 | E5: Score 1 | F5: Score 2 | G5: Venue | H5: Result | I5: Date | J5: Time
A6: 1 | B6: 1 | C6: A2 | D6: A5 | G6: CST Artificial Turf | H6: =IF(OR(E6="",F6=""),"",IF(E6>F6,C6&" win",IF(F6>E6,D6&" win","Draw"))) | I6: =IFERROR(INDEX('Match Schedule'!$B$6:$B$79,MATCH(A6,'Match Schedule'!#REF!,0)),"") | J6: =IFERROR(INDEX('Match Schedule'!$D$6:$D$79,MATCH(A6,'Match Schedule'!#REF!,0)),"")
A7: 2 | B7: 1 | C7: A3 | D7: A4 | H7: =IF(OR(E7="",F7=""),"",IF(E7>F7,C7&" win",IF(F7>E7,D7&" win","Draw"))) | I7: =IFERROR(INDEX('Match Schedule'!$B$6:$B$79,MATCH(A7,'Match Schedule'!#REF!,0)),"") | J7: =IFERROR(INDEX('Match Schedule'!$D$6:$D$79,MATCH(A7,'Match Schedule'!#REF!,0)),"")
A8: 3 | B8: 2 | C8: A1 | D8: A5 | H8: =IF(OR(E8="",F8=""),"",IF(E8>F8,C8&" win",IF(F8>E8,D8&" win","Draw"))) | I8: =IFERROR(INDEX('Match Schedule'!$B$6:$B$79,MATCH(A8,'Match Schedule'!#REF!,0)),"") | J8: =IFERROR(INDEX('Match Schedule'!$D$6:$D$79,MATCH(A8,'Match Schedule'!#REF!,0)),"")
A9: 4 | B9: 2 | C9: A2 | D9: A3 | H9: =IF(OR(E9="",F9=""),"",IF(E9>F9,C9&" win",IF(F9>E9,D9&" win","Draw"))) | I9: =IFERROR(INDEX('Match Schedule'!$B$6:$B$79,MATCH(A9,'Match Schedule'!#REF!,0)),"") | J9: =IFERROR(INDEX('Match Schedule'!$D$6:$D$79,MATCH(A9,'Match Schedule'!#REF!,0)),"")
A10: 5 | B10: 3 | C10: A1 | D10: A4 | H10: =IF(OR(E10="",F10=""),"",IF(E10>F10,C10&" win",IF(F10>E10,D10&" win","Draw"))) | I10: =IFERROR(INDEX('Match Schedule'!$B$6:$B$79,MATCH(A10,'Match Schedule'!#REF!,0)),"") | J10: =IFERROR(INDEX('Match Schedule'!$D$6:$D$79,MATCH(A10,'Match Schedule'!#REF!,0)),"")
A11: 6 | B11: 3 | C11: A5 | D11: A3 | H11: =IF(OR(E11="",F11=""),"",IF(E11>F11,C11&" win",IF(F11>E11,D11&" win","Draw"))) | I11: =IFERROR(INDEX('Match Schedule'!$B$6:$B$79,MATCH(A11,'Match Schedule'!#REF!,0)),"") | J11: =IFERROR(INDEX('Match Schedule'!$D$6:$D$79,MATCH(A11,'Match Schedule'!#REF!,0)),"")
A12: 7 | B12: 4 | C12: A1 | D12: A3 | H12: =IF(OR(E12="",F12=""),"",IF(E12>F12,C12&" win",IF(F12>E12,D12&" win","Draw"))) | I12: =IFERROR(INDEX('Match Schedule'!$B$6:$B$79,MATCH(A12,'Match Schedule'!#REF!,0)),"") | J12: =IFERROR(INDEX('Match Schedule'!$D$6:$D$79,MATCH(A12,'Match Schedule'!#REF!,0)),"")
A13: 8 | B13: 4 | C13: A4 | D13: A2 | H13: =IF(OR(E13="",F13=""),"",IF(E13>F13,C13&" win",IF(F13>E13,D13&" win","Draw"))) | I13: =IFERROR(INDEX('Match Schedule'!$B$6:$B$79,MATCH(A13,'Match Schedule'!#REF!,0)),"") | J13: =IFERROR(INDEX('Match Schedule'!$D$6:$D$79,MATCH(A13,'Match Schedule'!#REF!,0)),"")
A14: 9 | B14: 5 | C14: A1 | D14: A2 | H14: =IF(OR(E14="",F14=""),"",IF(E14>F14,C14&" win",IF(F14>E14,D14&" win","Draw"))) | I14: =IFERROR(INDEX('Match Schedule'!$B$6:$B$79,MATCH(A14,'Match Schedule'!#REF!,0)),"") | J14: =IFERROR(INDEX('Match Schedule'!$D$6:$D$79,MATCH(A14,'Match Schedule'!#REF!,0)),"")
A15: 10 | B15: 5 | C15: A4 | D15: A5 | H15: =IF(OR(E15="",F15=""),"",IF(E15>F15,C15&" win",IF(F15>E15,D15&" win","Draw"))) | I15: =IFERROR(INDEX('Match Schedule'!$B$6:$B$79,MATCH(A15,'Match Schedule'!#REF!,0)),"") | J15: =IFERROR(INDEX('Match Schedule'!$D$6:$D$79,MATCH(A15,'Match Schedule'!#REF!,0)),"")
A17: GROUP B
A18: Match No. | B18: Match Day | C18: Team 1 | D18: Team 2 | E18: Score 1 | F18: Score 2 | G18: Venue | H18: Result | I18: Date | J18: Time
A19: 11 | B19: 1 | C19: B1 | D19: B4 | G19: CST Artificial Turf | H19: =IF(OR(E19="",F19=""),"",IF(E19>F19,C19&" win",IF(F19>E19,D19&" win","Draw"))) | I19: =IFERROR(INDEX('Match Schedule'!$B$6:$B$79,MATCH(A19,'Match Schedule'!#REF!,0)),"") | J19: =IFERROR(INDEX('Match Schedule'!$D$6:$D$79,MATCH(A19,'Match Schedule'!#REF!,0)),"")
A20: 12 | B20: 1 | C20: B2 | D20: B3 | H20: =IF(OR(E20="",F20=""),"",IF(E20>F20,C20&" win",IF(F20>E20,D20&" win","Draw"))) | I20: =IFERROR(INDEX('Match Schedule'!$B$6:$B$79,MATCH(A20,'Match Schedule'!#REF!,0)),"") | J20: =IFERROR(INDEX('Match Schedule'!$D$6:$D$79,MATCH(A20,'Match Schedule'!#REF!,0)),"")
A21: 13 | B21: 2 | C21: B1 | D21: B3 | H21: =IF(OR(E21="",F21=""),"",IF(E21>F21,C21&" win",IF(F21>E21,D21&" win","Draw"))) | I21: =IFERROR(INDEX('Match Schedule'!$B$6:$B$79,MATCH(A21,'Match Schedule'!#REF!,0)),"") | J21: =IFERROR(INDEX('Match Schedule'!$D$6:$D$79,MATCH(A21,'Match Schedule'!#REF!,0)),"")
A22: 14 | B22: 2 | C22: B4 | D22: B2 | H22: =IF(OR(E22="",F22=""),"",IF(E22>F22,C22&" win",IF(F22>E22,D22&" win","Draw"))) | I22: =IFERROR(INDEX('Match Schedule'!$B$6:$B$79,MATCH(A22,'Match Schedule'!#REF!,0)),"") | J22: =IFERROR(INDEX('Match Schedule'!$D$6:$D$79,MATCH(A22,'Match Schedule'!#REF!,0)),"")
A23: 15 | B23: 3 | C23: B1 | D23: B2 | H23: =IF(OR(E23="",F23=""),"",IF(E23>F23,C23&" win",IF(F23>E23,D23&" win","Draw"))) | I23: =IFERROR(INDEX('Match Schedule'!$B$6:$B$79,MATCH(A23,'Match Schedule'!#REF!,0)),"") | J23: =IFERROR(INDEX('Match Schedule'!$D$6:$D$79,MATCH(A23,'Match Schedule'!#REF!,0)),"")
A24: 16 | B24: 3 | C24: B3 | D24: B4 | H24: =IF(OR(E24="",F24=""),"",IF(E24>F24,C24&" win",IF(F24>E24,D24&" win","Draw"))) | I24: =IFERROR(INDEX('Match Schedule'!$B$6:$B$79,MATCH(A24,'Match Schedule'!#REF!,0)),"") | J24: =IFERROR(INDEX('Match Schedule'!$D$6:$D$79,MATCH(A24,'Match Schedule'!#REF!,0)),"")
A26: GROUP C
A27: Match No. | B27: Match Day | C27: Team 1 | D27: Team 2 | E27: Score 1 | F27: Score 2 | G27: Venue | H27: Result | I27: Date | J27: Time
A28: 17 | B28: 1 | C28: C1 | D28: C4 | G28: CST Artificial Turf | H28: =IF(OR(E28="",F28=""),"",IF(E28>F28,C28&" win",IF(F28>E28,D28&" win","Draw"))) | I28: =IFERROR(INDEX('Match Schedule'!$B$6:$B$79,MATCH(A28,'Match Schedule'!#REF!,0)),"") | J28: =IFERROR(INDEX('Match Schedule'!$D$6:$D$79,MATCH(A28,'Match Schedule'!#REF!,0)),"")
A29: 18 | B29: 1 | C29: C2 | D29: C3 | H29: =IF(OR(E29="",F29=""),"",IF(E29>F29,C29&" win",IF(F29>E29,D29&" win","Draw"))) | I29: =IFERROR(INDEX('Match Schedule'!$B$6:$B$79,MATCH(A29,'Match Schedule'!#REF!,0)),"") | J29: =IFERROR(INDEX('Match Schedule'!$D$6:$D$79,MATCH(A29,'Match Schedule'!#REF!,0)),"")
A30: 19 | B30: 2 | C30: C1 | D30: C3 | H30: =IF(OR(E30="",F30=""),"",IF(E30>F30,C30&" win",IF(F30>E30,D30&" win","Draw"))) | I30: =IFERROR(INDEX('Match Schedule'!$B$6:$B$79,MATCH(A30,'Match Schedule'!#REF!,0)),"") | J30: =IFERROR(INDEX('Match Schedule'!$D$6:$D$79,MATCH(A30,'Match Schedule'!#REF!,0)),"")
A31: 20 | B31: 2 | C31: C4 | D31: C2 | H31: =IF(OR(E31="",F31=""),"",IF(E31>F31,C31&" win",IF(F31>E31,D31&" win","Draw"))) | I31: =IFERROR(INDEX('Match Schedule'!$B$6:$B$79,MATCH(A31,'Match Schedule'!#REF!,0)),"") | J31: =IFERROR(INDEX('Match Schedule'!$D$6:$D$79,MATCH(A31,'Match Schedule'!#REF!,0)),"")
A32: 21 | B32: 3 | C32: C1 | D32: C2 | H32: =IF(OR(E32="",F32=""),"",IF(E32>F32,C32&" win",IF(F32>E32,D32&" win","Draw"))) | I32: =IFERROR(INDEX('Match Schedule'!$B$6:$B$79,MATCH(A32,'Match Schedule'!#REF!,0)),"") | J32: =IFERROR(INDEX('Match Schedule'!$D$6:$D$79,MATCH(A32,'Match Schedule'!#REF!,0)),"")
A33: 22 | B33: 3 | C33: C3 | D33: C4 | H33: =IF(OR(E33="",F33=""),"",IF(E33>F33,C33&" win",IF(F33>E33,D33&" win","Draw"))) | I33: =IFERROR(INDEX('Match Schedule'!$B$6:$B$79,MATCH(A33,'Match Schedule'!#REF!,0)),"") | J33: =IFERROR(INDEX('Match Schedule'!$D$6:$D$79,MATCH(A33,'Match Schedule'!#REF!,0)),"")
A35: GROUP D
A36: Match No. | B36: Match Day | C36: Team 1 | D36: Team 2 | E36: Score 1 | F36: Score 2 | G36: Venue | H36: Result | I36: Date | J36: Time
A37: 23 | B37: 1 | C37: D1 | D37: D4 | G37: CST Artificial Turf | H37: =IF(OR(E37="",F37=""),"",IF(E37>F37,C37&" win",IF(F37>E37,D37&" win","Draw"))) | I37: =IFERROR(INDEX('Match Schedule'!$B$6:$B$79,MATCH(A37,'Match Schedule'!#REF!,0)),"") | J37: =IFERROR(INDEX('Match Schedule'!$D$6:$D$79,MATCH(A37,'Match Schedule'!#REF!,0)),"")
A38: 24 | B38: 1 | C38: D2 | D38: D3 | H38: =IF(OR(E38="",F38=""),"",IF(E38>F38,C38&" win",IF(F38>E38,D38&" win","Draw"))) | I38: =IFERROR(INDEX('Match Schedule'!$B$6:$B$79,MATCH(A38,'Match Schedule'!#REF!,0)),"") | J38: =IFERROR(INDEX('Match Schedule'!$D$6:$D$79,MATCH(A38,'Match Schedule'!#REF!,0)),"")
A39: 25 | B39: 2 | C39: D1 | D39: D3 | H39: =IF(OR(E39="",F39=""),"",IF(E39>F39,C39&" win",IF(F39>E39,D39&" win","Draw"))) | I39: =IFERROR(INDEX('Match Schedule'!$B$6:$B$79,MATCH(A39,'Match Schedule'!#REF!,0)),"") | J39: =IFERROR(INDEX('Match Schedule'!$D$6:$D$79,MATCH(A39,'Match Schedule'!#REF!,0)),"")
A40: 26 | B40: 2 | C40: D4 | D40: D2 | H40: =IF(OR(E40="",F40=""),"",IF(E40>F40,C40&" win",IF(F40>E40,D40&" win","Draw"))) | I40: =IFERROR(INDEX('Match Schedule'!$B$6:$B$79,MATCH(A40,'Match Schedule'!#REF!,0)),"") | J40: =IFERROR(INDEX('Match Schedule'!$D$6:$D$79,MATCH(A40,'Match Schedule'!#REF!,0)),"")
A41: 27 | B41: 3 | C41: D1 | D41: D2 | H41: =IF(OR(E41="",F41=""),"",IF(E41>F41,C41&" win",IF(F41>E41,D41&" win","Draw"))) | I41: =IFERROR(INDEX('Match Schedule'!$B$6:$B$79,MATCH(A41,'Match Schedule'!#REF!,0)),"") | J41: =IFERROR(INDEX('Match Schedule'!$D$6:$D$79,MATCH(A41,'Match Schedule'!#REF!,0)),"")
A42: 28 | B42: 3 | C42: D3 | D42: D4 | H42: =IF(OR(E42="",F42=""),"",IF(E42>F42,C42&" win",IF(F42>E42,D42&" win","Draw"))) | I42: =IFERROR(INDEX('Match Schedule'!$B$6:$B$79,MATCH(A42,'Match Schedule'!#REF!,0)),"") | J42: =IFERROR(INDEX('Match Schedule'!$D$6:$D$79,MATCH(A42,'Match Schedule'!#REF!,0)),"")
A44: GROUP E
A45: Match No. | B45: Match Day | C45: Team 1 | D45: Team 2 | E45: Score 1 | F45: Score 2 | G45: Venue | H45: Result | I45: Date | J45: Time
...

Sheet Standings
A1: GROUP STANDINGS (AUTO-CALCULATED FROM FIXTURE RESULTS)
A2: Updates automatically once scores are entered on the "Group Fixtures" sheet. Points: Win=3, Draw=1, Loss=0.
A4: GROUP A
A5: Team | B5: P | C5: W | D5: D | E5: L | F5: GF | G5: GA | H5: GD | I5: Pts | J5: Rank
A6: A1 | B6: =SUMPRODUCT(('Group Fixtures'!$C$6:$C$15=$A6)*('Group Fixtures'!$E$6:$E$15<>""))+SUMPRODUCT(('Group Fixtures'!$D$6:$D$15=$A6)*('Group Fixtures'!$F$6:$F$15<>"")) -> 0 | C6: =SUMPRODUCT(('Group Fixtures'!$C$6:$C$15=$A6)*('Group Fixtures'!$E$6:$E$15<>"")*('Group Fixtures'!$E$6:$E$15>'Group Fixtures'!$F$6:$F$15))+SUMPRODUCT(('Group Fixtures'!$D$6:$D$15=$A6)*('Group Fixtures'!$F$6:$F$15<>"")*('Group Fixtures'!$F$6:$F$15>'Group Fixtures'!$E$6:$E$15)) -> 0 | D6: =SUMPRODUCT(('Group Fixtures'!$C$6:$C$15=$A6)*('Group Fixtures'!$E$6:$E$15<>"")*('Group Fixtures'!$E$6:$E$15='Group Fixtures'!$F$6:$F$15))+SUMPRODUCT(('Group Fixtures'!$D$6:$D$15=$A6)*('Group Fixtures'!$F$6:$F$15<>"")*('Group Fixtures'!$E$6:$E$15='Group Fixtures'!$F$6:$F$15)) -> 0 | E6: =B6-C6-D6 -> 0 | F6: =SUMIF('Group Fixtures'!$C$6:$C$15,$A6,'Group Fixtures'!$E$6:$E$15)+SUMIF('Group Fixtures'!$D$6:$D$15,$A6,'Group Fixtures'!$F$6:$F$15) -> 0 | G6: =SUMIF('Group Fixtures'!$C$6:$C$15,$A6,'Group Fixtures'!$F$6:$F$15)+SUMIF('Group Fixtures'!$D$6:$D$15,$A6,'Group Fixtures'!$E$6:$E$15) -> 0 | H6: =F6-G6 -> 0 | I6: =C6*3+D6*1 -> 0 | J6: =RANK(K6,$K$6:$K$10,0) -> 1 | K6: =I6*1000+H6*10-ROW()*0.0000001 -> -6e-07
A7: A2 | B7: =SUMPRODUCT(('Group Fixtures'!$C$6:$C$15=$A7)*('Group Fixtures'!$E$6:$E$15<>""))+SUMPRODUCT(('Group Fixtures'!$D$6:$D$15=$A7)*('Group Fixtures'!$F$6:$F$15<>"")) -> 0 | C7: =SUMPRODUCT(('Group Fixtures'!$C$6:$C$15=$A7)*('Group Fixtures'!$E$6:$E$15<>"")*('Group Fixtures'!$E$6:$E$15>'Group Fixtures'!$F$6:$F$15))+SUMPRODUCT(('Group Fixtures'!$D$6:$D$15=$A7)*('Group Fixtures'!$F$6:$F$15<>"")*('Group Fixtures'!$F$6:$F$15>'Group Fixtures'!$E$6:$E$15)) -> 0 | D7: =SUMPRODUCT(('Group Fixtures'!$C$6:$C$15=$A7)*('Group Fixtures'!$E$6:$E$15<>"")*('Group Fixtures'!$E$6:$E$15='Group Fixtures'!$F$6:$F$15))+SUMPRODUCT(('Group Fixtures'!$D$6:$D$15=$A7)*('Group Fixtures'!$F$6:$F$15<>"")*('Group Fixtures'!$E$6:$E$15='Group Fixtures'!$F$6:$F$15)) -> 0 | E7: =B7-C7-D7 -> 0 | F7: =SUMIF('Group Fixtures'!$C$6:$C$15,$A7,'Group Fixtures'!$E$6:$E$15)+SUMIF('Group Fixtures'!$D$6:$D$15,$A7,'Group Fixtures'!$F$6:$F$15) -> 0 | G7: =SUMIF('Group Fixtures'!$C$6:$C$15,$A7,'Group Fixtures'!$F$6:$F$15)+SUMIF('Group Fixtures'!$D$6:$D$15,$A7,'Group Fixtures'!$E$6:$E$15) -> 0 | H7: =F7-G7 -> 0 | I7: =C7*3+D7*1 -> 0 | J7: =RANK(K7,$K$6:$K$10,0) -> 2 | K7: =I7*1000+H7*10-ROW()*0.0000001 -> -7e-07
A8: A3 | B8: =SUMPRODUCT(('Group Fixtures'!$C$6:$C$15=$A8)*('Group Fixtures'!$E$6:$E$15<>""))+SUMPRODUCT(('Group Fixtures'!$D$6:$D$15=$A8)*('Group Fixtures'!$F$6:$F$15<>"")) -> 0 | C8: =SUMPRODUCT(('Group Fixtures'!$C$6:$C$15=$A8)*('Group Fixtures'!$E$6:$E$15<>"")*('Group Fixtures'!$E$6:$E$15>'Group Fixtures'!$F$6:$F$15))+SUMPRODUCT(('Group Fixtures'!$D$6:$D$15=$A8)*('Group Fixtures'!$F$6:$F$15<>"")*('Group Fixtures'!$F$6:$F$15>'Group Fixtures'!$E$6:$E$15)) -> 0 | D8: =SUMPRODUCT(('Group Fixtures'!$C$6:$C$15=$A8)*('Group Fixtures'!$E$6:$E$15<>"")*('Group Fixtures'!$E$6:$E$15='Group Fixtures'!$F$6:$F$15))+SUMPRODUCT(('Group Fixtures'!$D$6:$D$15=$A8)*('Group Fixtures'!$F$6:$F$15<>"")*('Group Fixtures'!$E$6:$E$15='Group Fixtures'!$F$6:$F$15)) -> 0 | E8: =B8-C8-D8 -> 0 | F8: =SUMIF('Group Fixtures'!$C$6:$C$15,$A8,'Group Fixtures'!$E$6:$E$15)+SUMIF('Group Fixtures'!$D$6:$D$15,$A8,'Group Fixtures'!$F$6:$F$15) -> 0 | G8: =SUMIF('Group Fixtures'!$C$6:$C$15,$A8,'Group Fixtures'!$F$6:$F$15)+SUMIF('Group Fixtures'!$D$6:$D$15,$A8,'Group Fixtures'!$E$6:$E$15) -> 0 | H8: =F8-G8 -> 0 | I8: =C8*3+D8*1 -> 0 | J8: =RANK(K8,$K$6:$K$10,0) -> 3 | K8: =I8*1000+H8*10-ROW()*0.0000001 -> -8e-07
A9: A4 | B9: =SUMPRODUCT(('Group Fixtures'!$C$6:$C$15=$A9)*('Group Fixtures'!$E$6:$E$15<>""))+SUMPRODUCT(('Group Fixtures'!$D$6:$D$15=$A9)*('Group Fixtures'!$F$6:$F$15<>"")) -> 0 | C9: =SUMPRODUCT(('Group Fixtures'!$C$6:$C$15=$A9)*('Group Fixtures'!$E$6:$E$15<>"")*('Group Fixtures'!$E$6:$E$15>'Group Fixtures'!$F$6:$F$15))+SUMPRODUCT(('Group Fixtures'!$D$6:$D$15=$A9)*('Group Fixtures'!$F$6:$F$15<>"")*('Group Fixtures'!$F$6:$F$15>'Group Fixtures'!$E$6:$E$15)) -> 0 | D9: =SUMPRODUCT(('Group Fixtures'!$C$6:$C$15=$A9)*('Group Fixtures'!$E$6:$E$15<>"")*('Group Fixtures'!$E$6:$E$15='Group Fixtures'!$F$6:$F$15))+SUMPRODUCT(('Group Fixtures'!$D$6:$D$15=$A9)*('Group Fixtures'!$F$6:$F$15<>"")*('Group Fixtures'!$E$6:$E$15='Group Fixtures'!$F$6:$F$15)) -> 0 | E9: =B9-C9-D9 -> 0 | F9: =SUMIF('Group Fixtures'!$C$6:$C$15,$A9,'Group Fixtures'!$E$6:$E$15)+SUMIF('Group Fixtures'!$D$6:$D$15,$A9,'Group Fixtures'!$F$6:$F$15) -> 0 | G9: =SUMIF('Group Fixtures'!$C$6:$C$15,$A9,'Group Fixtures'!$F$6:$F$15)+SUMIF('Group Fixtures'!$D$6:$D$15,$A9,'Group Fixtures'!$E$6:$E$15) -> 0 | H9: =F9-G9 -> 0 | I9: =C9*3+D9*1 -> 0 | J9: =RANK(K9,$K$6:$K$10,0) -> 4 | K9: =I9*1000+H9*10-ROW()*0.0000001 -> -9e-07
A10: A5 | B10: =SUMPRODUCT(('Group Fixtures'!$C$6:$C$15=$A10)*('Group Fixtures'!$E$6:$E$15<>""))+SUMPRODUCT(('Group Fixtures'!$D$6:$D$15=$A10)*('Group Fixtures'!$F$6:$F$15<>"")) -> 0 | C10: =SUMPRODUCT(('Group Fixtures'!$C$6:$C$15=$A10)*('Group Fixtures'!$E$6:$E$15<>"")*('Group Fixtures'!$E$6:$E$15>'Group Fixtures'!$F$6:$F$15))+SUMPRODUCT(('Group Fixtures'!$D$6:$D$15=$A10)*('Group Fixtures'!$F$6:$F$15<>"")*('Group Fixtures'!$F$6:$F$15>'Group Fixtures'!$E$6:$E$15)) -> 0 | D10: =SUMPRODUCT(('Group Fixtures'!$C$6:$C$15=$A10)*('Group Fixtures'!$E$6:$E$15<>"")*('Group Fixtures'!$E$6:$E$15='Group Fixtures'!$F$6:$F$15))+SUMPRODUCT(('Group Fixtures'!$D$6:$D$15=$A10)*('Group Fixtures'!$F$6:$F$15<>"")*('Group Fixtures'!$E$6:$E$15='Group Fixtures'!$F$6:$F$15)) -> 0 | E10: =B10-C10-D10 -> 0 | F10: =SUMIF('Group Fixtures'!$C$6:$C$15,$A10,'Group Fixtures'!$E$6:$E$15)+SUMIF('Group Fixtures'!$D$6:$D$15,$A10,'Group Fixtures'!$F$6:$F$15) -> 0 | G10: =SUMIF('Group Fixtures'!$C$6:$C$15,$A10,'Group Fixtures'!$F$6:$F$15)+SUMIF('Group Fixtures'!$D$6:$D$15,$A10,'Group Fixtures'!$E$6:$E$15) -> 0 | H10: =F10-G10 -> 0 | I10: =C10*3+D10*1 -> 0 | J10: =RANK(K10,$K$6:$K$10,0) -> 5 | K10: =I10*1000+H10*10-ROW()*0.0000001 -> -1e-06
A12: GROUP B
A13: Team | B13: P | C13: W | D13: D | E13: L | F13: GF | G13: GA | H13: GD | I13: Pts | J13: Rank
A14: B1 | B14: =SUMPRODUCT(('Group Fixtures'!$C$19:$C$24=$A14)*('Group Fixtures'!$E$19:$E$24<>""))+SUMPRODUCT(('Group Fixtures'!$D$19:$D$24=$A14)*('Group Fixtures'!$F$19:$F$24<>"")) -> 0 | C14: =SUMPRODUCT(('Group Fixtures'!$C$19:$C$24=$A14)*('Group Fixtures'!$E$19:$E$24<>"")*('Group Fixtures'!$E$19:$E$24>'Group Fixtures'!$F$19:$F$24))+SUMPRODUCT(('Group Fixtures'!$D$19:$D$24=$A14)*('Group Fixtures'!$F$19:$F$24<>"")*('Group Fixtures'!$F$19:$F$24>'Group Fixtures'!$E$19:$E$24)) -> 0 | D14: =SUMPRODUCT(('Group Fixtures'!$C$19:$C$24=$A14)*('Group Fixtures'!$E$19:$E$24<>"")*('Group Fixtures'!$E$19:$E$24='Group Fixtures'!$F$19:$F$24))+SUMPRODUCT(('Group Fixtures'!$D$19:$D$24=$A14)*('Group Fixtures'!$F$19:$F$24<>"")*('Group Fixtures'!$E$19:$E$24='Group Fixtures'!$F$19:$F$24)) -> 0 | E14: =B14-C14-D14 -> 0 | F14: =SUMIF('Group Fixtures'!$C$19:$C$24,$A14,'Group Fixtures'!$E$19:$E$24)+SUMIF('Group Fixtures'!$D$19:$D$24,$A14,'Group Fixtures'!$F$19:$F$24) -> 0 | G14: =SUMIF('Group Fixtures'!$C$19:$C$24,$A14,'Group Fixtures'!$F$19:$F$24)+SUMIF('Group Fixtures'!$D$19:$D$24,$A14,'Group Fixtures'!$E$19:$E$24) -> 0 | H14: =F14-G14 -> 0 | I14: =C14*3+D14*1 -> 0 | J14: =RANK(K14,$K$14:$K$17,0) -> 1 | K14: =I14*1000+H14*10-ROW()*0.0000001 -> -1.4e-06
A15: B2 | B15: =SUMPRODUCT(('Group Fixtures'!$C$19:$C$24=$A15)*('Group Fixtures'!$E$19:$E$24<>""))+SUMPRODUCT(('Group Fixtures'!$D$19:$D$24=$A15)*('Group Fixtures'!$F$19:$F$24<>"")) -> 0 | C15: =SUMPRODUCT(('Group Fixtures'!$C$19:$C$24=$A15)*('Group Fixtures'!$E$19:$E$24<>"")*('Group Fixtures'!$E$19:$E$24>'Group Fixtures'!$F$19:$F$24))+SUMPRODUCT(('Group Fixtures'!$D$19:$D$24=$A15)*('Group Fixtures'!$F$19:$F$24<>"")*('Group Fixtures'!$F$19:$F$24>'Group Fixtures'!$E$19:$E$24)) -> 0 | D15: =SUMPRODUCT(('Group Fixtures'!$C$19:$C$24=$A15)*('Group Fixtures'!$E$19:$E$24<>"")*('Group Fixtures'!$E$19:$E$24='Group Fixtures'!$F$19:$F$24))+SUMPRODUCT(('Group Fixtures'!$D$19:$D$24=$A15)*('Group Fixtures'!$F$19:$F$24<>"")*('Group Fixtures'!$E$19:$E$24='Group Fixtures'!$F$19:$F$24)) -> 0 | E15: =B15-C15-D15 -> 0 | F15: =SUMIF('Group Fixtures'!$C$19:$C$24,$A15,'Group Fixtures'!$E$19:$E$24)+SUMIF('Group Fixtures'!$D$19:$D$24,$A15,'Group Fixtures'!$F$19:$F$24) -> 0 | G15: =SUMIF('Group Fixtures'!$C$19:$C$24,$A15,'Group Fixtures'!$F$19:$F$24)+SUMIF('Group Fixtures'!$D$19:$D$24,$A15,'Group Fixtures'!$E$19:$E$24) -> 0 | H15: =F15-G15 -> 0 | I15: =C15*3+D15*1 -> 0 | J15: =RANK(K15,$K$14:$K$17,0) -> 2 | K15: =I15*1000+H15*10-ROW()*0.0000001 -> -1.5e-06
A16: B3 | B16: =SUMPRODUCT(('Group Fixtures'!$C$19:$C$24=$A16)*('Group Fixtures'!$E$19:$E$24<>""))+SUMPRODUCT(('Group Fixtures'!$D$19:$D$24=$A16)*('Group Fixtures'!$F$19:$F$24<>"")) -> 0 | C16: =SUMPRODUCT(('Group Fixtures'!$C$19:$C$24=$A16)*('Group Fixtures'!$E$19:$E$24<>"")*('Group Fixtures'!$E$19:$E$24>'Group Fixtures'!$F$19:$F$24))+SUMPRODUCT(('Group Fixtures'!$D$19:$D$24=$A16)*('Group Fixtures'!$F$19:$F$24<>"")*('Group Fixtures'!$F$19:$F$24>'Group Fixtures'!$E$19:$E$24)) -> 0 | D16: =SUMPRODUCT(('Group Fixtures'!$C$19:$C$24=$A16)*('Group Fixtures'!$E$19:$E$24<>"")*('Group Fixtures'!$E$19:$E$24='Group Fixtures'!$F$19:$F$24))+SUMPRODUCT(('Group Fixtures'!$D$19:$D$24=$A16)*('Group Fixtures'!$F$19:$F$24<>"")*('Group Fixtures'!$E$19:$E$24='Group Fixtures'!$F$19:$F$24)) -> 0 | E16: =B16-C16-D16 -> 0 | F16: =SUMIF('Group Fixtures'!$C$19:$C$24,$A16,'Group Fixtures'!$E$19:$E$24)+SUMIF('Group Fixtures'!$D$19:$D$24,$A16,'Group Fixtures'!$F$19:$F$24) -> 0 | G16: =SUMIF('Group Fixtures'!$C$19:$C$24,$A16,'Group Fixtures'!$F$19:$F$24)+SUMIF('Group Fixtures'!$D$19:$D$24,$A16,'Group Fixtures'!$E$19:$E$24) -> 0 | H16: =F16-G16 -> 0 | I16: =C16*3+D16*1 -> 0 | J16: =RANK(K16,$K$14:$K$17,0) -> 3 | K16: =I16*1000+H16*10-ROW()*0.0000001 -> -1.6e-06
A17: B4 | B17: =SUMPRODUCT(('Group Fixtures'!$C$19:$C$24=$A17)*('Group Fixtures'!$E$19:$E$24<>""))+SUMPRODUCT(('Group Fixtures'!$D$19:$D$24=$A17)*('Group Fixtures'!$F$19:$F$24<>"")) -> 0 | C17: =SUMPRODUCT(('Group Fixtures'!$C$19:$C$24=$A17)*('Group Fixtures'!$E$19:$E$24<>"")*('Group Fixtures'!$E$19:$E$24>'Group Fixtures'!$F$19:$F$24))+SUMPRODUCT(('Group Fixtures'!$D$19:$D$24=$A17)*('Group Fixtures'!$F$19:$F$24<>"")*('Group Fixtures'!$F$19:$F$24>'Group Fixtures'!$E$19:$E$24)) -> 0 | D17: =SUMPRODUCT(('Group Fixtures'!$C$19:$C$24=$A17)*('Group Fixtures'!$E$19:$E$24<>"")*('Group Fixtures'!$E$19:$E$24='Group Fixtures'!$F$19:$F$24))+SUMPRODUCT(('Group Fixtures'!$D$19:$D$24=$A17)*('Group Fixtures'!$F$19:$F$24<>"")*('Group Fixtures'!$E$19:$E$24='Group Fixtures'!$F$19:$F$24)) -> 0 | E17: =B17-C17-D17 -> 0 | F17: =SUMIF('Group Fixtures'!$C$19:$C$24,$A17,'Group Fixtures'!$E$19:$E$24)+SUMIF('Group Fixtures'!$D$19:$D$24,$A17,'Group Fixtures'!$F$19:$F$24) -> 0 | G17: =SUMIF('Group Fixtures'!$C$19:$C$24,$A17,'Group Fixtures'!$F$19:$F$24)+SUMIF('Group Fixtures'!$D$19:$D$24,$A17,'Group Fixtures'!$E$19:$E$24) -> 0 | H17: =F17-G17 -> 0 | I17: =C17*3+D17*1 -> 0 | J17: =RANK(K17,$K$14:$K$17,0) -> 4 | K17: =I17*1000+H17*10-ROW()*0.0000001 -> -1.7e-06
A19: GROUP C
A20: Team | B20: P | C20: W | D20: D | E20: L | F20: GF | G20: GA | H20: GD | I20: Pts | J20: Rank
A21: C1 | B21: =SUMPRODUCT(('Group Fixtures'!$C$28:$C$33=$A21)*('Group Fixtures'!$E$28:$E$33<>""))+SUMPRODUCT(('Group Fixtures'!$D$28:$D$33=$A21)*('Group Fixtures'!$F$28:$F$33<>"")) -> 0 | C21: =SUMPRODUCT(('Group Fixtures'!$C$28:$C$33=$A21)*('Group Fixtures'!$E$28:$E$33<>"")*('Group Fixtures'!$E$28:$E$33>'Group Fixtures'!$F$28:$F$33))+SUMPRODUCT(('Group Fixtures'!$D$28:$D$33=$A21)*('Group Fixtures'!$F$28:$F$33<>"")*('Group Fixtures'!$F$28:$F$33>'Group Fixtures'!$E$28:$E$33)) -> 0 | D21: =SUMPRODUCT(('Group Fixtures'!$C$28:$C$33=$A21)*('Group Fixtures'!$E$28:$E$33<>"")*('Group Fixtures'!$E$28:$E$33='Group Fixtures'!$F$28:$F$33))+SUMPRODUCT(('Group Fixtures'!$D$28:$D$33=$A21)*('Group Fixtures'!$F$28:$F$33<>"")*('Group Fixtures'!$E$28:$E$33='Group Fixtures'!$F$28:$F$33)) -> 0 | E21: =B21-C21-D21 -> 0 | F21: =SUMIF('Group Fixtures'!$C$28:$C$33,$A21,'Group Fixtures'!$E$28:$E$33)+SUMIF('Group Fixtures'!$D$28:$D$33,$A21,'Group Fixtures'!$F$28:$F$33) -> 0 | G21: =SUMIF('Group Fixtures'!$C$28:$C$33,$A21,'Group Fixtures'!$F$28:$F$33)+SUMIF('Group Fixtures'!$D$28:$D$33,$A21,'Group Fixtures'!$E$28:$E$33) -> 0 | H21: =F21-G21 -> 0 | I21: =C21*3+D21*1 -> 0 | J21: =RANK(K21,$K$21:$K$24,0) -> 1 | K21: =I21*1000+H21*10-ROW()*0.0000001 -> -2.1e-06
A22: C2 | B22: =SUMPRODUCT(('Group Fixtures'!$C$28:$C$33=$A22)*('Group Fixtures'!$E$28:$E$33<>""))+SUMPRODUCT(('Group Fixtures'!$D$28:$D$33=$A22)*('Group Fixtures'!$F$28:$F$33<>"")) -> 0 | C22: =SUMPRODUCT(('Group Fixtures'!$C$28:$C$33=$A22)*('Group Fixtures'!$E$28:$E$33<>"")*('Group Fixtures'!$E$28:$E$33>'Group Fixtures'!$F$28:$F$33))+SUMPRODUCT(('Group Fixtures'!$D$28:$D$33=$A22)*('Group Fixtures'!$F$28:$F$33<>"")*('Group Fixtures'!$F$28:$F$33>'Group Fixtures'!$E$28:$E$33)) -> 0 | D22: =SUMPRODUCT(('Group Fixtures'!$C$28:$C$33=$A22)*('Group Fixtures'!$E$28:$E$33<>"")*('Group Fixtures'!$E$28:$E$33='Group Fixtures'!$F$28:$F$33))+SUMPRODUCT(('Group Fixtures'!$D$28:$D$33=$A22)*('Group Fixtures'!$F$28:$F$33<>"")*('Group Fixtures'!$E$28:$E$33='Group Fixtures'!$F$28:$F$33)) -> 0 | E22: =B22-C22-D22 -> 0 | F22: =SUMIF('Group Fixtures'!$C$28:$C$33,$A22,'Group Fixtures'!$E$28:$E$33)+SUMIF('Group Fixtures'!$D$28:$D$33,$A22,'Group Fixtures'!$F$28:$F$33) -> 0 | G22: =SUMIF('Group Fixtures'!$C$28:$C$33,$A22,'Group Fixtures'!$F$28:$F$33)+SUMIF('Group Fixtures'!$D$28:$D$33,$A22,'Group Fixtures'!$E$28:$E$33) -> 0 | H22: =F22-G22 -> 0 | I22: =C22*3+D22*1 -> 0 | J22: =RANK(K22,$K$21:$K$24,0) -> 2 | K22: =I22*1000+H22*10-ROW()*0.0000001 -> -2.2e-06
A23: C3 | B23: =SUMPRODUCT(('Group Fixtures'!$C$28:$C$33=$A23)*('Group Fixtures'!$E$28:$E$33<>""))+SUMPRODUCT(('Group Fixtures'!$D$28:$D$33=$A23)*('Group Fixtures'!$F$28:$F$33<>"")) -> 0 | C23: =SUMPRODUCT(('Group Fixtures'!$C$28:$C$33=$A23)*('Group Fixtures'!$E$28:$E$33<>"")*('Group Fixtures'!$E$28:$E$33>'Group Fixtures'!$F$28:$F$33))+SUMPRODUCT(('Group Fixtures'!$D$28:$D$33=$A23)*('Group Fixtures'!$F$28:$F$33<>"")*('Group Fixtures'!$F$28:$F$33>'Group Fixtures'!$E$28:$E$33)) -> 0 | D23: =SUMPRODUCT(('Group Fixtures'!$C$28:$C$33=$A23)*('Group Fixtures'!$E$28:$E$33<>"")*('Group Fixtures'!$E$28:$E$33='Group Fixtures'!$F$28:$F$33))+SUMPRODUCT(('Group Fixtures'!$D$28:$D$33=$A23)*('Group Fixtures'!$F$28:$F$33<>"")*('Group Fixtures'!$E$28:$E$33='Group Fixtures'!$F$28:$F$33)) -> 0 | E23: =B23-C23-D23 -> 0 | F23: =SUMIF('Group Fixtures'!$C$28:$C$33,$A23,'Group Fixtures'!$E$28:$E$33)+SUMIF('Group Fixtures'!$D$28:$D$33,$A23,'Group Fixtures'!$F$28:$F$33) -> 0 | G23: =SUMIF('Group Fixtures'!$C$28:$C$33,$A23,'Group Fixtures'!$F$28:$F$33)+SUMIF('Group Fixtures'!$D$28:$D$33,$A23,'Group Fixtures'!$E$28:$E$33) -> 0 | H23: =F23-G23 -> 0 | I23: =C23*3+D23*1 -> 0 | J23: =RANK(K23,$K$21:$K$24,0) -> 3 | K23: =I23*1000+H23*10-ROW()*0.0000001 -> -2.3e-06
A24: C4 | B24: =SUMPRODUCT(('Group Fixtures'!$C$28:$C$33=$A24)*('Group Fixtures'!$E$28:$E$33<>""))+SUMPRODUCT(('Group Fixtures'!$D$28:$D$33=$A24)*('Group Fixtures'!$F$28:$F$33<>"")) -> 0 | C24: =SUMPRODUCT(('Group Fixtures'!$C$28:$C$33=$A24)*('Group Fixtures'!$E$28:$E$33<>"")*('Group Fixtures'!$E$28:$E$33>'Group Fixtures'!$F$28:$F$33))+SUMPRODUCT(('Group Fixtures'!$D$28:$D$33=$A24)*('Group Fixtures'!$F$28:$F$33<>"")*('Group Fixtures'!$F$28:$F$33>'Group Fixtures'!$E$28:$E$33)) -> 0 | D24: =SUMPRODUCT(('Group Fixtures'!$C$28:$C$33=$A24)*('Group Fixtures'!$E$28:$E$33<>"")*('Group Fixtures'!$E$28:$E$33='Group Fixtures'!$F$28:$F$33))+SUMPRODUCT(('Group Fixtures'!$D$28:$D$33=$A24)*('Group Fixtures'!$F$28:$F$33<>"")*('Group Fixtures'!$E$28:$E$33='Group Fixtures'!$F$28:$F$33)) -> 0 | E24: =B24-C24-D24 -> 0 | F24: =SUMIF('Group Fixtures'!$C$28:$C$33,$A24,'Group Fixtures'!$E$28:$E$33)+SUMIF('Group Fixtures'!$D$28:$D$33,$A24,'Group Fixtures'!$F$28:$F$33) -> 0 | G24: =SUMIF('Group Fixtures'!$C$28:$C$33,$A24,'Group Fixtures'!$F$28:$F$33)+SUMIF('Group Fixtures'!$D$28:$D$33,$A24,'Group Fixtures'!$E$28:$E$33) -> 0 | H24: =F24-G24 -> 0 | I24: =C24*3+D24*1 -> 0 | J24: =RANK(K24,$K$21:$K$24,0) -> 4 | K24: =I24*1000+H24*10-ROW()*0.0000001 -> -2.4e-06
A26: GROUP D
A27: Team | B27: P | C27: W | D27: D | E27: L | F27: GF | G27: GA | H27: GD | I27: Pts | J27: Rank
A28: D1 | B28: =SUMPRODUCT(('Group Fixtures'!$C$37:$C$42=$A28)*('Group Fixtures'!$E$37:$E$42<>""))+SUMPRODUCT(('Group Fixtures'!$D$37:$D$42=$A28)*('Group Fixtures'!$F$37:$F$42<>"")) -> 0 | C28: =SUMPRODUCT(('Group Fixtures'!$C$37:$C$42=$A28)*('Group Fixtures'!$E$37:$E$42<>"")*('Group Fixtures'!$E$37:$E$42>'Group Fixtures'!$F$37:$F$42))+SUMPRODUCT(('Group Fixtures'!$D$37:$D$42=$A28)*('Group Fixtures'!$F$37:$F$42<>"")*('Group Fixtures'!$F$37:$F$42>'Group Fixtures'!$E$37:$E$42)) -> 0 | D28: =SUMPRODUCT(('Group Fixtures'!$C$37:$C$42=$A28)*('Group Fixtures'!$E$37:$E$42<>"")*('Group Fixtures'!$E$37:$E$42='Group Fixtures'!$F$37:$F$42))+SUMPRODUCT(('Group Fixtures'!$D$37:$D$42=$A28)*('Group Fixtures'!$F$37:$F$42<>"")*('Group Fixtures'!$E$37:$E$42='Group Fixtures'!$F$37:$F$42)) -> 0 | E28: =B28-C28-D28 -> 0 | F28: =SUMIF('Group Fixtures'!$C$37:$C$42,$A28,'Group Fixtures'!$E$37:$E$42)+SUMIF('Group Fixtures'!$D$37:$D$42,$A28,'Group Fixtures'!$F$37:$F$42) -> 0 | G28: =SUMIF('Group Fixtures'!$C$37:$C$42,$A28,'Group Fixtures'!$F$37:$F$42)+SUMIF('Group Fixtures'!$D$37:$D$42,$A28,'Group Fixtures'!$E$37:$E$42) -> 0 | H28: =F28-G28 -> 0 | I28: =C28*3+D28*1 -> 0 | J28: =RANK(K28,$K$28:$K$31,0) -> 1 | K28: =I28*1000+H28*10-ROW()*0.0000001 -> -2.8e-06
A29: D2 | B29: =SUMPRODUCT(('Group Fixtures'!$C$37:$C$42=$A29)*('Group Fixtures'!$E$37:$E$42<>""))+SUMPRODUCT(('Group Fixtures'!$D$37:$D$42=$A29)*('Group Fixtures'!$F$37:$F$42<>"")) -> 0 | C29: =SUMPRODUCT(('Group Fixtures'!$C$37:$C$42=$A29)*('Group Fixtures'!$E$37:$E$42<>"")*('Group Fixtures'!$E$37:$E$42>'Group Fixtures'!$F$37:$F$42))+SUMPRODUCT(('Group Fixtures'!$D$37:$D$42=$A29)*('Group Fixtures'!$F$37:$F$42<>"")*('Group Fixtures'!$F$37:$F$42>'Group Fixtures'!$E$37:$E$42)) -> 0 | D29: =SUMPRODUCT(('Group Fixtures'!$C$37:$C$42=$A29)*('Group Fixtures'!$E$37:$E$42<>"")*('Group Fixtures'!$E$37:$E$42='Group Fixtures'!$F$37:$F$42))+SUMPRODUCT(('Group Fixtures'!$D$37:$D$42=$A29)*('Group Fixtures'!$F$37:$F$42<>"")*('Group Fixtures'!$E$37:$E$42='Group Fixtures'!$F$37:$F$42)) -> 0 | E29: =B29-C29-D29 -> 0 | F29: =SUMIF('Group Fixtures'!$C$37:$C$42,$A29,'Group Fixtures'!$E$37:$E$42)+SUMIF('Group Fixtures'!$D$37:$D$42,$A29,'Group Fixtures'!$F$37:$F$42) -> 0 | G29: =SUMIF('Group Fixtures'!$C$37:$C$42,$A29,'Group Fixtures'!$F$37:$F$42)+SUMIF('Group Fixtures'!$D$37:$D$42,$A29,'Group Fixtures'!$E$37:$E$42) -> 0 | H29: =F29-G29 -> 0 | I29: =C29*3+D29*1 -> 0 | J29: =RANK(K29,$K$28:$K$31,0) -> 2 | K29: =I29*1000+H29*10-ROW()*0.0000001 -> -2.9e-06
A30: D3 | B30: =SUMPRODUCT(('Group Fixtures'!$C$37:$C$42=$A30)*('Group Fixtures'!$E$37:$E$42<>""))+SUMPRODUCT(('Group Fixtures'!$D$37:$D$42=$A30)*('Group Fixtures'!$F$37:$F$42<>"")) -> 0 | C30: =SUMPRODUCT(('Group Fixtures'!$C$37:$C$42=$A30)*('Group Fixtures'!$E$37:$E$42<>"")*('Group Fixtures'!$E$37:$E$42>'Group Fixtures'!$F$37:$F$42))+SUMPRODUCT(('Group Fixtures'!$D$37:$D$42=$A30)*('Group Fixtures'!$F$37:$F$42<>"")*('Group Fixtures'!$F$37:$F$42>'Group Fixtures'!$E$37:$E$42)) -> 0 | D30: =SUMPRODUCT(('Group Fixtures'!$C$37:$C$42=$A30)*('Group Fixtures'!$E$37:$E$42<>"")*('Group Fixtures'!$E$37:$E$42='Group Fixtures'!$F$37:$F$42))+SUMPRODUCT(('Group Fixtures'!$D$37:$D$42=$A30)*('Group Fixtures'!$F$37:$F$42<>"")*('Group Fixtures'!$E$37:$E$42='Group Fixtures'!$F$37:$F$42)) -> 0 | E30: =B30-C30-D30 -> 0 | F30: =SUMIF('Group Fixtures'!$C$37:$C$42,$A30,'Group Fixtures'!$E$37:$E$42)+SUMIF('Group Fixtures'!$D$37:$D$42,$A30,'Group Fixtures'!$F$37:$F$42) -> 0 | G30: =SUMIF('Group Fixtures'!$C$37:$C$42,$A30,'Group Fixtures'!$F$37:$F$42)+SUMIF('Group Fixtures'!$D$37:$D$42,$A30,'Group Fixtures'!$E$37:$E$42) -> 0 | H30: =F30-G30 -> 0 | I30: =C30*3+D30*1 -> 0 | J30: =RANK(K30,$K$28:$K$31,0) -> 3 | K30: =I30*1000+H30*10-ROW()*0.0000001 -> -3e-06
A31: D4 | B31: =SUMPRODUCT(('Group Fixtures'!$C$37:$C$42=$A31)*('Group Fixtures'!$E$37:$E$42<>""))+SUMPRODUCT(('Group Fixtures'!$D$37:$D$42=$A31)*('Group Fixtures'!$F$37:$F$42<>"")) -> 0 | C31: =SUMPRODUCT(('Group Fixtures'!$C$37:$C$42=$A31)*('Group Fixtures'!$E$37:$E$42<>"")*('Group Fixtures'!$E$37:$E$42>'Group Fixtures'!$F$37:$F$42))+SUMPRODUCT(('Group Fixtures'!$D$37:$D$42=$A31)*('Group Fixtures'!$F$37:$F$42<>"")*('Group Fixtures'!$F$37:$F$42>'Group Fixtures'!$E$37:$E$42)) -> 0 | D31: =SUMPRODUCT(('Group Fixtures'!$C$37:$C$42=$A31)*('Group Fixtures'!$E$37:$E$42<>"")*('Group Fixtures'!$E$37:$E$42='Group Fixtures'!$F$37:$F$42))+SUMPRODUCT(('Group Fixtures'!$D$37:$D$42=$A31)*('Group Fixtures'!$F$37:$F$42<>"")*('Group Fixtures'!$E$37:$E$42='Group Fixtures'!$F$37:$F$42)) -> 0 | E31: =B31-C31-D31 -> 0 | F31: =SUMIF('Group Fixtures'!$C$37:$C$42,$A31,'Group Fixtures'!$E$37:$E$42)+SUMIF('Group Fixtures'!$D$37:$D$42,$A31,'Group Fixtures'!$F$37:$F$42) -> 0 | G31: =SUMIF('Group Fixtures'!$C$37:$C$42,$A31,'Group Fixtures'!$F$37:$F$42)+SUMIF('Group Fixtures'!$D$37:$D$42,$A31,'Group Fixtures'!$E$37:$E$42) -> 0 | H31: =F31-G31 -> 0 | I31: =C31*3+D31*1 -> 0 | J31: =RANK(K31,$K$28:$K$31,0) -> 4 | K31: =I31*1000+H31*10-ROW()*0.0000001 -> -3.1e-06
A33: GROUP E
A34: Team | B34: P | C34: W | D34: D | E34: L | F34: GF | G34: GA | H34: GD | I34: Pts | J34: Rank
A35: E1 | B35: =SUMPRODUCT(('Group Fixtures'!$C$46:$C$51=$A35)*('Group Fixtures'!$E$46:$E$51<>""))+SUMPRODUCT(('Group Fixtures'!$D$46:$D$51=$A35)*('Group Fixtures'!$F$46:$F$51<>"")) -> 0 | C35: =SUMPRODUCT(('Group Fixtures'!$C$46:$C$51=$A35)*('Group Fixtures'!$E$46:$E$51<>"")*('Group Fixtures'!$E$46:$E$51>'Group Fixtures'!$F$46:$F$51))+SUMPRODUCT(('Group Fixtures'!$D$46:$D$51=$A35)*('Group Fixtures'!$F$46:$F$51<>"")*('Group Fixtures'!$F$46:$F$51>'Group Fixtures'!$E$46:$E$51)) -> 0 | D35: =SUMPRODUCT(('Group Fixtures'!$C$46:$C$51=$A35)*('Group Fixtures'!$E$46:$E$51<>"")*('Group Fixtures'!$E$46:$E$51='Group Fixtures'!$F$46:$F$51))+SUMPRODUCT(('Group Fixtures'!$D$46:$D$51=$A35)*('Group Fixtures'!$F$46:$F$51<>"")*('Group Fixtures'!$E$46:$E$51='Group Fixtures'!$F$46:$F$51)) -> 0 | E35: =B35-C35-D35 -> 0 | F35: =SUMIF('Group Fixtures'!$C$46:$C$51,$A35,'Group Fixtures'!$E$46:$E$51)+SUMIF('Group Fixtures'!$D$46:$D$51,$A35,'Group Fixtures'!$F$46:$F$51) -> 0 | G35: =SUMIF('Group Fixtures'!$C$46:$C$51,$A35,'Group Fixtures'!$F$46:$F$51)+SUMIF('Group Fixtures'!$D$46:$D$51,$A35,'Group Fixtures'!$E$46:$E$51) -> 0 | H35: =F35-G35 -> 0 | I35: =C35*3+D35*1 -> 0 | J35: =RANK(K35,$K$35:$K$38,0) -> 1 | K35: =I35*1000+H35*10-ROW()*0.0000001 -> -3.5e-06
A36: E2 | B36: =SUMPRODUCT(('Group Fixtures'!$C$46:$C$51=$A36)*('Group Fixtures'!$E$46:$E$51<>""))+SUMPRODUCT(('Group Fixtures'!$D$46:$D$51=$A36)*('Group Fixtures'!$F$46:$F$51<>"")) -> 0 | C36: =SUMPRODUCT(('Group Fixtures'!$C$46:$C$51=$A36)*('Group Fixtures'!$E$46:$E$51<>"")*('Group Fixtures'!$E$46:$E$51>'Group Fixtures'!$F$46:$F$51))+SUMPRODUCT(('Group Fixtures'!$D$46:$D$51=$A36)*('Group Fixtures'!$F$46:$F$51<>"")*('Group Fixtures'!$F$46:$F$51>'Group Fixtures'!$E$46:$E$51)) -> 0 | D36: =SUMPRODUCT(('Group Fixtures'!$C$46:$C$51=$A36)*('Group Fixtures'!$E$46:$E$51<>"")*('Group Fixtures'!$E$46:$E$51='Group Fixtures'!$F$46:$F$51))+SUMPRODUCT(('Group Fixtures'!$D$46:$D$51=$A36)*('Group Fixtures'!$F$46:$F$51<>"")*('Group Fixtures'!$E$46:$E$51='Group Fixtures'!$F$46:$F$51)) -> 0 | E36: =B36-C36-D36 -> 0 | F36: =SUMIF('Group Fixtures'!$C$46:$C$51,$A36,'Group Fixtures'!$E$46:$E$51)+SUMIF('Group Fixtures'!$D$46:$D$51,$A36,'Group Fixtures'!$F$46:$F$51) -> 0 | G36: =SUMIF('Group Fixtures'!$C$46:$C$51,$A36,'Group Fixtures'!$F$46:$F$51)+SUMIF('Group Fixtures'!$D$46:$D$51,$A36,'Group Fixtures'!$E$46:$E$51) -> 0 | H36: =F36-G36 -> 0 | I36: =C36*3+D36*1 -> 0 | J36: =RANK(K36,$K$35:$K$38,0) -> 2 | K36: =I36*1000+H36*10-ROW()*0.0000001 -> -3.6e-06
